[2025-05-18 21:40:21] [ERROR] [src.services.producao_services] [PRODUCAO] Erro inesperado ao processar dados de 1970: (psycopg2.OperationalError) connection to server at "localhost" (::1), port 5433 failed: Connection refused (0x0000274D/10061)
	Is the server running on that host and accepting TCP/IP connections?
connection to server at "localhost" (127.0.0.1), port 5433 failed: Connection refused (0x0000274D/10061)
	Is the server running on that host and accepting TCP/IP connections?

(Background on this error at: https://sqlalche.me/e/20/e3q8)
Traceback (most recent call last):
  File "D:\Arquivos Baixados\Projeto postech\tech-challenge-1\venv\Lib\site-packages\sqlalchemy\engine\base.py", line 145, in __init__
    self._dbapi_connection = engine.raw_connection()
                             ~~~~~~~~~~~~~~~~~~~~~^^
  File "D:\Arquivos Baixados\Projeto postech\tech-challenge-1\venv\Lib\site-packages\sqlalchemy\engine\base.py", line 3297, in raw_connection
    return self.pool.connect()
           ~~~~~~~~~~~~~~~~~^^
  File "D:\Arquivos Baixados\Projeto postech\tech-challenge-1\venv\Lib\site-packages\sqlalchemy\pool\base.py", line 449, in connect
    return _ConnectionFairy._checkout(self)
           ~~~~~~~~~~~~~~~~~~~~~~~~~~^^^^^^
  File "D:\Arquivos Baixados\Projeto postech\tech-challenge-1\venv\Lib\site-packages\sqlalchemy\pool\base.py", line 1264, in _checkout
    fairy = _ConnectionRecord.checkout(pool)
  File "D:\Arquivos Baixados\Projeto postech\tech-challenge-1\venv\Lib\site-packages\sqlalchemy\pool\base.py", line 713, in checkout
    rec = pool._do_get()
  File "D:\Arquivos Baixados\Projeto postech\tech-challenge-1\venv\Lib\site-packages\sqlalchemy\pool\impl.py", line 179, in _do_get
    with util.safe_reraise():
         ~~~~~~~~~~~~~~~~~^^
  File "D:\Arquivos Baixados\Projeto postech\tech-challenge-1\venv\Lib\site-packages\sqlalchemy\util\langhelpers.py", line 224, in __exit__
    raise exc_value.with_traceback(exc_tb)
  File "D:\Arquivos Baixados\Projeto postech\tech-challenge-1\venv\Lib\site-packages\sqlalchemy\pool\impl.py", line 177, in _do_get
    return self._create_connection()
           ~~~~~~~~~~~~~~~~~~~~~~~^^
  File "D:\Arquivos Baixados\Projeto postech\tech-challenge-1\venv\Lib\site-packages\sqlalchemy\pool\base.py", line 390, in _create_connection
    return _ConnectionRecord(self)
  File "D:\Arquivos Baixados\Projeto postech\tech-challenge-1\venv\Lib\site-packages\sqlalchemy\pool\base.py", line 675, in __init__
    self.__connect()
    ~~~~~~~~~~~~~~^^
  File "D:\Arquivos Baixados\Projeto postech\tech-challenge-1\venv\Lib\site-packages\sqlalchemy\pool\base.py", line 901, in __connect
    with util.safe_reraise():
         ~~~~~~~~~~~~~~~~~^^
  File "D:\Arquivos Baixados\Projeto postech\tech-challenge-1\venv\Lib\site-packages\sqlalchemy\util\langhelpers.py", line 224, in __exit__
    raise exc_value.with_traceback(exc_tb)
  File "D:\Arquivos Baixados\Projeto postech\tech-challenge-1\venv\Lib\site-packages\sqlalchemy\pool\base.py", line 897, in __connect
    self.dbapi_connection = connection = pool._invoke_creator(self)
                                         ~~~~~~~~~~~~~~~~~~~~^^^^^^
  File "D:\Arquivos Baixados\Projeto postech\tech-challenge-1\venv\Lib\site-packages\sqlalchemy\engine\create.py", line 646, in connect
    return dialect.connect(*cargs, **cparams)
           ~~~~~~~~~~~~~~~^^^^^^^^^^^^^^^^^^^
  File "D:\Arquivos Baixados\Projeto postech\tech-challenge-1\venv\Lib\site-packages\sqlalchemy\engine\default.py", line 625, in connect
    return self.loaded_dbapi.connect(*cargs, **cparams)  # type: ignore[no-any-return]  # NOQA: E501
           ~~~~~~~~~~~~~~~~~~~~~~~~~^^^^^^^^^^^^^^^^^^^
  File "D:\Arquivos Baixados\Projeto postech\tech-challenge-1\venv\Lib\site-packages\psycopg2\__init__.py", line 135, in connect
    conn = _connect(dsn, connection_factory=connection_factory, **kwasync)
psycopg2.OperationalError: connection to server at "localhost" (::1), port 5433 failed: Connection refused (0x0000274D/10061)
	Is the server running on that host and accepting TCP/IP connections?
connection to server at "localhost" (127.0.0.1), port 5433 failed: Connection refused (0x0000274D/10061)
	Is the server running on that host and accepting TCP/IP connections?


The above exception was the direct cause of the following exception:

Traceback (most recent call last):
  File "D:\Arquivos Baixados\Projeto postech\tech-challenge-1\src\services\producao_services.py", line 36, in get_por_ano
    self._repo_raw.upsert(
    ~~~~~~~~~~~~~~~~~~~~~^
        endpoint="producao",
        ^^^^^^^^^^^^^^^^^^^^
    ...<2 lines>...
        payload=dados
        ^^^^^^^^^^^^^
    )
    ^
  File "D:\Arquivos Baixados\Projeto postech\tech-challenge-1\src\repositories\raw_repository.py", line 32, in upsert
    session.execute(upsert_stmt)
    ~~~~~~~~~~~~~~~^^^^^^^^^^^^^
  File "D:\Arquivos Baixados\Projeto postech\tech-challenge-1\venv\Lib\site-packages\sqlalchemy\orm\session.py", line 2365, in execute
    return self._execute_internal(
           ~~~~~~~~~~~~~~~~~~~~~~^
        statement,
        ^^^^^^^^^^
    ...<4 lines>...
        _add_event=_add_event,
        ^^^^^^^^^^^^^^^^^^^^^^
    )
    ^
  File "D:\Arquivos Baixados\Projeto postech\tech-challenge-1\venv\Lib\site-packages\sqlalchemy\orm\session.py", line 2241, in _execute_internal
    conn = self._connection_for_bind(bind)
  File "D:\Arquivos Baixados\Projeto postech\tech-challenge-1\venv\Lib\site-packages\sqlalchemy\orm\session.py", line 2110, in _connection_for_bind
    return trans._connection_for_bind(engine, execution_options)
           ~~~~~~~~~~~~~~~~~~~~~~~~~~^^^^^^^^^^^^^^^^^^^^^^^^^^^
  File "<string>", line 2, in _connection_for_bind
  File "D:\Arquivos Baixados\Projeto postech\tech-challenge-1\venv\Lib\site-packages\sqlalchemy\orm\state_changes.py", line 139, in _go
    ret_value = fn(self, *arg, **kw)
  File "D:\Arquivos Baixados\Projeto postech\tech-challenge-1\venv\Lib\site-packages\sqlalchemy\orm\session.py", line 1189, in _connection_for_bind
    conn = bind.connect()
  File "D:\Arquivos Baixados\Projeto postech\tech-challenge-1\venv\Lib\site-packages\sqlalchemy\engine\base.py", line 3273, in connect
    return self._connection_cls(self)
           ~~~~~~~~~~~~~~~~~~~~^^^^^^
  File "D:\Arquivos Baixados\Projeto postech\tech-challenge-1\venv\Lib\site-packages\sqlalchemy\engine\base.py", line 147, in __init__
    Connection._handle_dbapi_exception_noconnection(
    ~~~~~~~~~~~~~~~~~~~~~~~~~~~~~~~~~~~~~~~~~~~~~~~^
        err, dialect, engine
        ^^^^^^^^^^^^^^^^^^^^
    )
    ^
  File "D:\Arquivos Baixados\Projeto postech\tech-challenge-1\venv\Lib\site-packages\sqlalchemy\engine\base.py", line 2436, in _handle_dbapi_exception_noconnection
    raise sqlalchemy_exception.with_traceback(exc_info[2]) from e
  File "D:\Arquivos Baixados\Projeto postech\tech-challenge-1\venv\Lib\site-packages\sqlalchemy\engine\base.py", line 145, in __init__
    self._dbapi_connection = engine.raw_connection()
                             ~~~~~~~~~~~~~~~~~~~~~^^
  File "D:\Arquivos Baixados\Projeto postech\tech-challenge-1\venv\Lib\site-packages\sqlalchemy\engine\base.py", line 3297, in raw_connection
    return self.pool.connect()
           ~~~~~~~~~~~~~~~~~^^
  File "D:\Arquivos Baixados\Projeto postech\tech-challenge-1\venv\Lib\site-packages\sqlalchemy\pool\base.py", line 449, in connect
    return _ConnectionFairy._checkout(self)
           ~~~~~~~~~~~~~~~~~~~~~~~~~~^^^^^^
  File "D:\Arquivos Baixados\Projeto postech\tech-challenge-1\venv\Lib\site-packages\sqlalchemy\pool\base.py", line 1264, in _checkout
    fairy = _ConnectionRecord.checkout(pool)
  File "D:\Arquivos Baixados\Projeto postech\tech-challenge-1\venv\Lib\site-packages\sqlalchemy\pool\base.py", line 713, in checkout
    rec = pool._do_get()
  File "D:\Arquivos Baixados\Projeto postech\tech-challenge-1\venv\Lib\site-packages\sqlalchemy\pool\impl.py", line 179, in _do_get
    with util.safe_reraise():
         ~~~~~~~~~~~~~~~~~^^
  File "D:\Arquivos Baixados\Projeto postech\tech-challenge-1\venv\Lib\site-packages\sqlalchemy\util\langhelpers.py", line 224, in __exit__
    raise exc_value.with_traceback(exc_tb)
  File "D:\Arquivos Baixados\Projeto postech\tech-challenge-1\venv\Lib\site-packages\sqlalchemy\pool\impl.py", line 177, in _do_get
    return self._create_connection()
           ~~~~~~~~~~~~~~~~~~~~~~~^^
  File "D:\Arquivos Baixados\Projeto postech\tech-challenge-1\venv\Lib\site-packages\sqlalchemy\pool\base.py", line 390, in _create_connection
    return _ConnectionRecord(self)
  File "D:\Arquivos Baixados\Projeto postech\tech-challenge-1\venv\Lib\site-packages\sqlalchemy\pool\base.py", line 675, in __init__
    self.__connect()
    ~~~~~~~~~~~~~~^^
  File "D:\Arquivos Baixados\Projeto postech\tech-challenge-1\venv\Lib\site-packages\sqlalchemy\pool\base.py", line 901, in __connect
    with util.safe_reraise():
         ~~~~~~~~~~~~~~~~~^^
  File "D:\Arquivos Baixados\Projeto postech\tech-challenge-1\venv\Lib\site-packages\sqlalchemy\util\langhelpers.py", line 224, in __exit__
    raise exc_value.with_traceback(exc_tb)
  File "D:\Arquivos Baixados\Projeto postech\tech-challenge-1\venv\Lib\site-packages\sqlalchemy\pool\base.py", line 897, in __connect
    self.dbapi_connection = connection = pool._invoke_creator(self)
                                         ~~~~~~~~~~~~~~~~~~~~^^^^^^
  File "D:\Arquivos Baixados\Projeto postech\tech-challenge-1\venv\Lib\site-packages\sqlalchemy\engine\create.py", line 646, in connect
    return dialect.connect(*cargs, **cparams)
           ~~~~~~~~~~~~~~~^^^^^^^^^^^^^^^^^^^
  File "D:\Arquivos Baixados\Projeto postech\tech-challenge-1\venv\Lib\site-packages\sqlalchemy\engine\default.py", line 625, in connect
    return self.loaded_dbapi.connect(*cargs, **cparams)  # type: ignore[no-any-return]  # NOQA: E501
           ~~~~~~~~~~~~~~~~~~~~~~~~~^^^^^^^^^^^^^^^^^^^
  File "D:\Arquivos Baixados\Projeto postech\tech-challenge-1\venv\Lib\site-packages\psycopg2\__init__.py", line 135, in connect
    conn = _connect(dsn, connection_factory=connection_factory, **kwasync)
sqlalchemy.exc.OperationalError: (psycopg2.OperationalError) connection to server at "localhost" (::1), port 5433 failed: Connection refused (0x0000274D/10061)
	Is the server running on that host and accepting TCP/IP connections?
connection to server at "localhost" (127.0.0.1), port 5433 failed: Connection refused (0x0000274D/10061)
	Is the server running on that host and accepting TCP/IP connections?

(Background on this error at: https://sqlalche.me/e/20/e3q8)
[2025-05-18 21:41:03] [ERROR] [src.services.comercializacao_services] [COMERCIALIZACAO] Erro inesperado ao processar dados de 2020: (psycopg2.OperationalError) connection to server at "localhost" (::1), port 5433 failed: Connection refused (0x0000274D/10061)
	Is the server running on that host and accepting TCP/IP connections?
connection to server at "localhost" (127.0.0.1), port 5433 failed: Connection refused (0x0000274D/10061)
	Is the server running on that host and accepting TCP/IP connections?

(Background on this error at: https://sqlalche.me/e/20/e3q8)
Traceback (most recent call last):
  File "D:\Arquivos Baixados\Projeto postech\tech-challenge-1\venv\Lib\site-packages\sqlalchemy\engine\base.py", line 145, in __init__
    self._dbapi_connection = engine.raw_connection()
                             ~~~~~~~~~~~~~~~~~~~~~^^
  File "D:\Arquivos Baixados\Projeto postech\tech-challenge-1\venv\Lib\site-packages\sqlalchemy\engine\base.py", line 3297, in raw_connection
    return self.pool.connect()
           ~~~~~~~~~~~~~~~~~^^
  File "D:\Arquivos Baixados\Projeto postech\tech-challenge-1\venv\Lib\site-packages\sqlalchemy\pool\base.py", line 449, in connect
    return _ConnectionFairy._checkout(self)
           ~~~~~~~~~~~~~~~~~~~~~~~~~~^^^^^^
  File "D:\Arquivos Baixados\Projeto postech\tech-challenge-1\venv\Lib\site-packages\sqlalchemy\pool\base.py", line 1264, in _checkout
    fairy = _ConnectionRecord.checkout(pool)
  File "D:\Arquivos Baixados\Projeto postech\tech-challenge-1\venv\Lib\site-packages\sqlalchemy\pool\base.py", line 713, in checkout
    rec = pool._do_get()
  File "D:\Arquivos Baixados\Projeto postech\tech-challenge-1\venv\Lib\site-packages\sqlalchemy\pool\impl.py", line 179, in _do_get
    with util.safe_reraise():
         ~~~~~~~~~~~~~~~~~^^
  File "D:\Arquivos Baixados\Projeto postech\tech-challenge-1\venv\Lib\site-packages\sqlalchemy\util\langhelpers.py", line 224, in __exit__
    raise exc_value.with_traceback(exc_tb)
  File "D:\Arquivos Baixados\Projeto postech\tech-challenge-1\venv\Lib\site-packages\sqlalchemy\pool\impl.py", line 177, in _do_get
    return self._create_connection()
           ~~~~~~~~~~~~~~~~~~~~~~~^^
  File "D:\Arquivos Baixados\Projeto postech\tech-challenge-1\venv\Lib\site-packages\sqlalchemy\pool\base.py", line 390, in _create_connection
    return _ConnectionRecord(self)
  File "D:\Arquivos Baixados\Projeto postech\tech-challenge-1\venv\Lib\site-packages\sqlalchemy\pool\base.py", line 675, in __init__
    self.__connect()
    ~~~~~~~~~~~~~~^^
  File "D:\Arquivos Baixados\Projeto postech\tech-challenge-1\venv\Lib\site-packages\sqlalchemy\pool\base.py", line 901, in __connect
    with util.safe_reraise():
         ~~~~~~~~~~~~~~~~~^^
  File "D:\Arquivos Baixados\Projeto postech\tech-challenge-1\venv\Lib\site-packages\sqlalchemy\util\langhelpers.py", line 224, in __exit__
    raise exc_value.with_traceback(exc_tb)
  File "D:\Arquivos Baixados\Projeto postech\tech-challenge-1\venv\Lib\site-packages\sqlalchemy\pool\base.py", line 897, in __connect
    self.dbapi_connection = connection = pool._invoke_creator(self)
                                         ~~~~~~~~~~~~~~~~~~~~^^^^^^
  File "D:\Arquivos Baixados\Projeto postech\tech-challenge-1\venv\Lib\site-packages\sqlalchemy\engine\create.py", line 646, in connect
    return dialect.connect(*cargs, **cparams)
           ~~~~~~~~~~~~~~~^^^^^^^^^^^^^^^^^^^
  File "D:\Arquivos Baixados\Projeto postech\tech-challenge-1\venv\Lib\site-packages\sqlalchemy\engine\default.py", line 625, in connect
    return self.loaded_dbapi.connect(*cargs, **cparams)  # type: ignore[no-any-return]  # NOQA: E501
           ~~~~~~~~~~~~~~~~~~~~~~~~~^^^^^^^^^^^^^^^^^^^
  File "D:\Arquivos Baixados\Projeto postech\tech-challenge-1\venv\Lib\site-packages\psycopg2\__init__.py", line 135, in connect
    conn = _connect(dsn, connection_factory=connection_factory, **kwasync)
psycopg2.OperationalError: connection to server at "localhost" (::1), port 5433 failed: Connection refused (0x0000274D/10061)
	Is the server running on that host and accepting TCP/IP connections?
connection to server at "localhost" (127.0.0.1), port 5433 failed: Connection refused (0x0000274D/10061)
	Is the server running on that host and accepting TCP/IP connections?


The above exception was the direct cause of the following exception:

Traceback (most recent call last):
  File "D:\Arquivos Baixados\Projeto postech\tech-challenge-1\src\services\comercializacao_services.py", line 36, in get_por_ano
    self._repo_raw.upsert(
    ~~~~~~~~~~~~~~~~~~~~~^
        endpoint="comercializacao",
        ^^^^^^^^^^^^^^^^^^^^^^^^^^^
    ...<2 lines>...
        payload=dados
        ^^^^^^^^^^^^^
    )
    ^
  File "D:\Arquivos Baixados\Projeto postech\tech-challenge-1\src\repositories\raw_repository.py", line 32, in upsert
    session.execute(upsert_stmt)
    ~~~~~~~~~~~~~~~^^^^^^^^^^^^^
  File "D:\Arquivos Baixados\Projeto postech\tech-challenge-1\venv\Lib\site-packages\sqlalchemy\orm\session.py", line 2365, in execute
    return self._execute_internal(
           ~~~~~~~~~~~~~~~~~~~~~~^
        statement,
        ^^^^^^^^^^
    ...<4 lines>...
        _add_event=_add_event,
        ^^^^^^^^^^^^^^^^^^^^^^
    )
    ^
  File "D:\Arquivos Baixados\Projeto postech\tech-challenge-1\venv\Lib\site-packages\sqlalchemy\orm\session.py", line 2241, in _execute_internal
    conn = self._connection_for_bind(bind)
  File "D:\Arquivos Baixados\Projeto postech\tech-challenge-1\venv\Lib\site-packages\sqlalchemy\orm\session.py", line 2110, in _connection_for_bind
    return trans._connection_for_bind(engine, execution_options)
           ~~~~~~~~~~~~~~~~~~~~~~~~~~^^^^^^^^^^^^^^^^^^^^^^^^^^^
  File "<string>", line 2, in _connection_for_bind
  File "D:\Arquivos Baixados\Projeto postech\tech-challenge-1\venv\Lib\site-packages\sqlalchemy\orm\state_changes.py", line 139, in _go
    ret_value = fn(self, *arg, **kw)
  File "D:\Arquivos Baixados\Projeto postech\tech-challenge-1\venv\Lib\site-packages\sqlalchemy\orm\session.py", line 1189, in _connection_for_bind
    conn = bind.connect()
  File "D:\Arquivos Baixados\Projeto postech\tech-challenge-1\venv\Lib\site-packages\sqlalchemy\engine\base.py", line 3273, in connect
    return self._connection_cls(self)
           ~~~~~~~~~~~~~~~~~~~~^^^^^^
  File "D:\Arquivos Baixados\Projeto postech\tech-challenge-1\venv\Lib\site-packages\sqlalchemy\engine\base.py", line 147, in __init__
    Connection._handle_dbapi_exception_noconnection(
    ~~~~~~~~~~~~~~~~~~~~~~~~~~~~~~~~~~~~~~~~~~~~~~~^
        err, dialect, engine
        ^^^^^^^^^^^^^^^^^^^^
    )
    ^
  File "D:\Arquivos Baixados\Projeto postech\tech-challenge-1\venv\Lib\site-packages\sqlalchemy\engine\base.py", line 2436, in _handle_dbapi_exception_noconnection
    raise sqlalchemy_exception.with_traceback(exc_info[2]) from e
  File "D:\Arquivos Baixados\Projeto postech\tech-challenge-1\venv\Lib\site-packages\sqlalchemy\engine\base.py", line 145, in __init__
    self._dbapi_connection = engine.raw_connection()
                             ~~~~~~~~~~~~~~~~~~~~~^^
  File "D:\Arquivos Baixados\Projeto postech\tech-challenge-1\venv\Lib\site-packages\sqlalchemy\engine\base.py", line 3297, in raw_connection
    return self.pool.connect()
           ~~~~~~~~~~~~~~~~~^^
  File "D:\Arquivos Baixados\Projeto postech\tech-challenge-1\venv\Lib\site-packages\sqlalchemy\pool\base.py", line 449, in connect
    return _ConnectionFairy._checkout(self)
           ~~~~~~~~~~~~~~~~~~~~~~~~~~^^^^^^
  File "D:\Arquivos Baixados\Projeto postech\tech-challenge-1\venv\Lib\site-packages\sqlalchemy\pool\base.py", line 1264, in _checkout
    fairy = _ConnectionRecord.checkout(pool)
  File "D:\Arquivos Baixados\Projeto postech\tech-challenge-1\venv\Lib\site-packages\sqlalchemy\pool\base.py", line 713, in checkout
    rec = pool._do_get()
  File "D:\Arquivos Baixados\Projeto postech\tech-challenge-1\venv\Lib\site-packages\sqlalchemy\pool\impl.py", line 179, in _do_get
    with util.safe_reraise():
         ~~~~~~~~~~~~~~~~~^^
  File "D:\Arquivos Baixados\Projeto postech\tech-challenge-1\venv\Lib\site-packages\sqlalchemy\util\langhelpers.py", line 224, in __exit__
    raise exc_value.with_traceback(exc_tb)
  File "D:\Arquivos Baixados\Projeto postech\tech-challenge-1\venv\Lib\site-packages\sqlalchemy\pool\impl.py", line 177, in _do_get
    return self._create_connection()
           ~~~~~~~~~~~~~~~~~~~~~~~^^
  File "D:\Arquivos Baixados\Projeto postech\tech-challenge-1\venv\Lib\site-packages\sqlalchemy\pool\base.py", line 390, in _create_connection
    return _ConnectionRecord(self)
  File "D:\Arquivos Baixados\Projeto postech\tech-challenge-1\venv\Lib\site-packages\sqlalchemy\pool\base.py", line 675, in __init__
    self.__connect()
    ~~~~~~~~~~~~~~^^
  File "D:\Arquivos Baixados\Projeto postech\tech-challenge-1\venv\Lib\site-packages\sqlalchemy\pool\base.py", line 901, in __connect
    with util.safe_reraise():
         ~~~~~~~~~~~~~~~~~^^
  File "D:\Arquivos Baixados\Projeto postech\tech-challenge-1\venv\Lib\site-packages\sqlalchemy\util\langhelpers.py", line 224, in __exit__
    raise exc_value.with_traceback(exc_tb)
  File "D:\Arquivos Baixados\Projeto postech\tech-challenge-1\venv\Lib\site-packages\sqlalchemy\pool\base.py", line 897, in __connect
    self.dbapi_connection = connection = pool._invoke_creator(self)
                                         ~~~~~~~~~~~~~~~~~~~~^^^^^^
  File "D:\Arquivos Baixados\Projeto postech\tech-challenge-1\venv\Lib\site-packages\sqlalchemy\engine\create.py", line 646, in connect
    return dialect.connect(*cargs, **cparams)
           ~~~~~~~~~~~~~~~^^^^^^^^^^^^^^^^^^^
  File "D:\Arquivos Baixados\Projeto postech\tech-challenge-1\venv\Lib\site-packages\sqlalchemy\engine\default.py", line 625, in connect
    return self.loaded_dbapi.connect(*cargs, **cparams)  # type: ignore[no-any-return]  # NOQA: E501
           ~~~~~~~~~~~~~~~~~~~~~~~~~^^^^^^^^^^^^^^^^^^^
  File "D:\Arquivos Baixados\Projeto postech\tech-challenge-1\venv\Lib\site-packages\psycopg2\__init__.py", line 135, in connect
    conn = _connect(dsn, connection_factory=connection_factory, **kwasync)
sqlalchemy.exc.OperationalError: (psycopg2.OperationalError) connection to server at "localhost" (::1), port 5433 failed: Connection refused (0x0000274D/10061)
	Is the server running on that host and accepting TCP/IP connections?
connection to server at "localhost" (127.0.0.1), port 5433 failed: Connection refused (0x0000274D/10061)
	Is the server running on that host and accepting TCP/IP connections?

(Background on this error at: https://sqlalche.me/e/20/e3q8)
[2025-05-20 18:21:40] [WARNING] [src.services.producao_service] Erro HTTP 404 ao acessar ano 1970; usando dados locais.
[2025-05-20 18:21:54] [WARNING] [src.services.comercializacao_service] Erro HTTP 404 ao acessar ano 1970; usando dados locais.
[2025-05-20 18:22:00] [WARNING] [src.services.processamento_service] Erro HTTP 404 ao acessar ano 1970; usando dados locais.
[2025-05-20 18:22:07] [WARNING] [src.services.importacao_service] Erro HTTP 404 ao acessar ano 1970; usando dados locais.
[2025-05-20 18:25:50] [WARNING] [src.services.importacao_service] Erro HTTP 404 ao acessar ano 1970; usando dados locais.
[2025-05-20 18:26:14] [WARNING] [src.services.exportacao_service] Erro HTTP 404 ao acessar ano 1970; usando dados locais.
[2025-05-20 18:26:51] [WARNING] [src.services.producao_service] Erro HTTP 404 ao acessar ano 1970; usando dados locais.
[2025-05-20 18:29:06] [WARNING] [src.services.comercializacao_service] Erro HTTP 404 ao acessar ano 1970; usando dados locais.
[2025-05-20 18:29:17] [WARNING] [src.services.processamento_service] Erro HTTP 404 ao acessar ano 1970; usando dados locais.
[2025-05-20 18:29:24] [WARNING] [src.services.importacao_service] Erro HTTP 404 ao acessar ano 1970; usando dados locais.
[2025-05-20 18:29:30] [WARNING] [src.services.exportacao_service] Erro HTTP 404 ao acessar ano 1970; usando dados locais.
[2025-05-20 19:19:21] [ERROR] [src.services.comercializacao_service] Erro inesperado ao processar dados de 1970; usando dados locais.
Traceback (most recent call last):
  File "/home/carloslessa/FCD/POSTECH/tech-challenge-1/src/services/comercializacao_service.py", line 42, in get_por_ano
    self._repo.salvar_ou_atualizar(dados, ano)
AttributeError: 'ComercializacaoRepository' object has no attribute 'salvar_ou_atualizar'
[2025-05-20 19:22:44] [WARNING] [src.services.comercializacao_service] Erro HTTP 404 ao acessar ano 1970; usando dados locais.
[2025-05-20 19:23:05] [WARNING] [src.services.comercializacao_service] Erro HTTP 404 ao acessar ano 1970; usando dados locais.
[2025-05-20 19:23:05] [WARNING] [src.services.comercializacao_service] Sem dados no site nem no banco para o ano 1970.
[2025-05-20 19:25:38] [WARNING] [src.services.comercializacao_service] Erro HTTP 404 ao acessar ano 1970; usando dados locais.
[2025-05-20 19:25:38] [WARNING] [src.services.comercializacao_service] Sem dados no site nem no banco para o ano 1970.
[2025-05-20 19:28:24] [WARNING] [src.services.comercializacao_service] Erro HTTP 404 ao acessar ano 1970; usando dados locais.
[2025-05-20 19:28:24] [ERROR] [src.services.comercializacao_service] Erro de persistência: Erro de conexão com o banco: (psycopg2.OperationalError) connection to server at "localhost" (127.0.0.1), port 5433 failed: Connection refused
	Is the server running on that host and accepting TCP/IP connections?

(Background on this error at: https://sqlalche.me/e/20/e3q8)
[2025-05-20 19:30:07] [WARNING] [src.services.comercializacao_service] Erro HTTP 404 ao acessar ano 1970; usando dados locais.
[2025-05-20 19:30:07] [WARNING] [src.services.comercializacao_service] Sem dados no site nem no banco para o ano 1970.
[2025-05-20 20:06:38] [WARNING] [src.services.producao_service] Erro HTTP 404 ao acessar ano 1970; usando dados locais.
[2025-05-20 20:06:47] [WARNING] [src.services.comercializacao_service] Erro HTTP 404 ao acessar ano 1970; usando dados locais.
[2025-05-20 20:06:55] [WARNING] [src.services.processamento_service] Erro HTTP 404 ao acessar ano 1970; usando dados locais.
[2025-05-20 20:07:04] [WARNING] [src.services.importacao_service] Erro HTTP 404 ao acessar ano 1970; usando dados locais.
[2025-05-20 20:07:10] [WARNING] [src.services.exportacao_service] Erro HTTP 404 ao acessar ano 1970; usando dados locais.
[2025-05-20 20:07:43] [WARNING] [src.services.producao_service] Erro HTTP 404 ao acessar ano 1970; usando dados locais.
[2025-05-20 20:07:43] [WARNING] [src.services.producao_service] Sem dados no site nem no banco para o ano 1970.
[2025-05-20 20:07:50] [WARNING] [src.services.comercializacao_service] Erro HTTP 404 ao acessar ano 1970; usando dados locais.
[2025-05-20 20:07:50] [WARNING] [src.services.comercializacao_service] Sem dados no site nem no banco para o ano 1970.
[2025-05-20 20:07:57] [WARNING] [src.services.processamento_service] Erro HTTP 404 ao acessar ano 1970; usando dados locais.
[2025-05-20 20:07:57] [WARNING] [src.services.processamento_service] Sem dados no site nem no banco para o ano 1970.
[2025-05-20 20:08:08] [WARNING] [src.services.importacao_service] Erro HTTP 404 ao acessar ano 1970; usando dados locais.
[2025-05-20 20:08:08] [WARNING] [src.services.importacao_service] Sem dados no site nem no banco para o ano 1970.
[2025-05-20 20:08:13] [WARNING] [src.services.exportacao_service] Erro HTTP 404 ao acessar ano 1970; usando dados locais.
[2025-05-20 20:08:13] [WARNING] [src.services.exportacao_service] Sem dados no site nem no banco para o ano 1970.
[2025-05-20 20:08:45] [WARNING] [src.services.producao_service] Erro HTTP 404 ao acessar ano 1970; usando dados locais.
[2025-05-20 20:08:45] [ERROR] [src.services.producao_service] Erro de persistência: Erro de conexão com o banco: (psycopg2.OperationalError) connection to server at "localhost" (127.0.0.1), port 5433 failed: Connection refused
	Is the server running on that host and accepting TCP/IP connections?

(Background on this error at: https://sqlalche.me/e/20/e3q8)
[2025-05-20 20:09:01] [WARNING] [src.services.comercializacao_service] Erro HTTP 404 ao acessar ano 1970; usando dados locais.
[2025-05-20 20:09:01] [ERROR] [src.services.comercializacao_service] Erro de persistência: Erro de conexão com o banco: (psycopg2.OperationalError) connection to server at "localhost" (127.0.0.1), port 5433 failed: Connection refused
	Is the server running on that host and accepting TCP/IP connections?

(Background on this error at: https://sqlalche.me/e/20/e3q8)
[2025-05-20 20:09:10] [WARNING] [src.services.processamento_service] Erro HTTP 404 ao acessar ano 1970; usando dados locais.
[2025-05-20 20:09:10] [ERROR] [src.services.processamento_service] Erro de persistência: Erro de conexão com o banco: (psycopg2.OperationalError) connection to server at "localhost" (127.0.0.1), port 5433 failed: Connection refused
	Is the server running on that host and accepting TCP/IP connections?

(Background on this error at: https://sqlalche.me/e/20/e3q8)
[2025-05-20 20:09:39] [WARNING] [src.services.importacao_service] Erro HTTP 404 ao acessar ano 1970; usando dados locais.
[2025-05-20 20:09:39] [ERROR] [src.services.importacao_service] Erro de persistência: Erro de conexão com o banco: (psycopg2.OperationalError) connection to server at "localhost" (127.0.0.1), port 5433 failed: Connection refused
	Is the server running on that host and accepting TCP/IP connections?

(Background on this error at: https://sqlalche.me/e/20/e3q8)
[2025-05-20 20:09:44] [WARNING] [src.services.exportacao_service] Erro HTTP 404 ao acessar ano 1970; usando dados locais.
[2025-05-20 20:09:44] [ERROR] [src.services.exportacao_service] Erro de persistência: Erro de conexão com o banco: (psycopg2.OperationalError) connection to server at "localhost" (127.0.0.1), port 5433 failed: Connection refused
	Is the server running on that host and accepting TCP/IP connections?

(Background on this error at: https://sqlalche.me/e/20/e3q8)
[2025-05-20 20:10:17] [ERROR] [src.services.producao_service] Erro inesperado ao processar dados de 1970; usando dados locais.
Traceback (most recent call last):
  File "/home/carloslessa/FCD/POSTECH/tech-challenge-1/venv/lib/python3.10/site-packages/sqlalchemy/engine/base.py", line 145, in __init__
    self._dbapi_connection = engine.raw_connection()
  File "/home/carloslessa/FCD/POSTECH/tech-challenge-1/venv/lib/python3.10/site-packages/sqlalchemy/engine/base.py", line 3297, in raw_connection
    return self.pool.connect()
  File "/home/carloslessa/FCD/POSTECH/tech-challenge-1/venv/lib/python3.10/site-packages/sqlalchemy/pool/base.py", line 449, in connect
    return _ConnectionFairy._checkout(self)
  File "/home/carloslessa/FCD/POSTECH/tech-challenge-1/venv/lib/python3.10/site-packages/sqlalchemy/pool/base.py", line 1264, in _checkout
    fairy = _ConnectionRecord.checkout(pool)
  File "/home/carloslessa/FCD/POSTECH/tech-challenge-1/venv/lib/python3.10/site-packages/sqlalchemy/pool/base.py", line 718, in checkout
    with util.safe_reraise():
  File "/home/carloslessa/FCD/POSTECH/tech-challenge-1/venv/lib/python3.10/site-packages/sqlalchemy/util/langhelpers.py", line 224, in __exit__
    raise exc_value.with_traceback(exc_tb)
  File "/home/carloslessa/FCD/POSTECH/tech-challenge-1/venv/lib/python3.10/site-packages/sqlalchemy/pool/base.py", line 716, in checkout
    dbapi_connection = rec.get_connection()
  File "/home/carloslessa/FCD/POSTECH/tech-challenge-1/venv/lib/python3.10/site-packages/sqlalchemy/pool/base.py", line 838, in get_connection
    self.__connect()
  File "/home/carloslessa/FCD/POSTECH/tech-challenge-1/venv/lib/python3.10/site-packages/sqlalchemy/pool/base.py", line 901, in __connect
    with util.safe_reraise():
  File "/home/carloslessa/FCD/POSTECH/tech-challenge-1/venv/lib/python3.10/site-packages/sqlalchemy/util/langhelpers.py", line 224, in __exit__
    raise exc_value.with_traceback(exc_tb)
  File "/home/carloslessa/FCD/POSTECH/tech-challenge-1/venv/lib/python3.10/site-packages/sqlalchemy/pool/base.py", line 897, in __connect
    self.dbapi_connection = connection = pool._invoke_creator(self)
  File "/home/carloslessa/FCD/POSTECH/tech-challenge-1/venv/lib/python3.10/site-packages/sqlalchemy/engine/create.py", line 646, in connect
    return dialect.connect(*cargs, **cparams)
  File "/home/carloslessa/FCD/POSTECH/tech-challenge-1/venv/lib/python3.10/site-packages/sqlalchemy/engine/default.py", line 625, in connect
    return self.loaded_dbapi.connect(*cargs, **cparams)  # type: ignore[no-any-return]  # NOQA: E501
  File "/home/carloslessa/FCD/POSTECH/tech-challenge-1/venv/lib/python3.10/site-packages/psycopg2/__init__.py", line 122, in connect
    conn = _connect(dsn, connection_factory=connection_factory, **kwasync)
psycopg2.OperationalError: connection to server at "localhost" (127.0.0.1), port 5433 failed: Connection refused
	Is the server running on that host and accepting TCP/IP connections?


The above exception was the direct cause of the following exception:

Traceback (most recent call last):
  File "/home/carloslessa/FCD/POSTECH/tech-challenge-1/src/repositories/raw_repository.py", line 71, in salvar_ou_atualizar
    session.execute(upsert_stmt)
  File "/home/carloslessa/FCD/POSTECH/tech-challenge-1/venv/lib/python3.10/site-packages/sqlalchemy/orm/session.py", line 2365, in execute
    return self._execute_internal(
  File "/home/carloslessa/FCD/POSTECH/tech-challenge-1/venv/lib/python3.10/site-packages/sqlalchemy/orm/session.py", line 2241, in _execute_internal
    conn = self._connection_for_bind(bind)
  File "/home/carloslessa/FCD/POSTECH/tech-challenge-1/venv/lib/python3.10/site-packages/sqlalchemy/orm/session.py", line 2110, in _connection_for_bind
    return trans._connection_for_bind(engine, execution_options)
  File "<string>", line 2, in _connection_for_bind
  File "/home/carloslessa/FCD/POSTECH/tech-challenge-1/venv/lib/python3.10/site-packages/sqlalchemy/orm/state_changes.py", line 139, in _go
    ret_value = fn(self, *arg, **kw)
  File "/home/carloslessa/FCD/POSTECH/tech-challenge-1/venv/lib/python3.10/site-packages/sqlalchemy/orm/session.py", line 1189, in _connection_for_bind
    conn = bind.connect()
  File "/home/carloslessa/FCD/POSTECH/tech-challenge-1/venv/lib/python3.10/site-packages/sqlalchemy/engine/base.py", line 3273, in connect
    return self._connection_cls(self)
  File "/home/carloslessa/FCD/POSTECH/tech-challenge-1/venv/lib/python3.10/site-packages/sqlalchemy/engine/base.py", line 147, in __init__
    Connection._handle_dbapi_exception_noconnection(
  File "/home/carloslessa/FCD/POSTECH/tech-challenge-1/venv/lib/python3.10/site-packages/sqlalchemy/engine/base.py", line 2436, in _handle_dbapi_exception_noconnection
    raise sqlalchemy_exception.with_traceback(exc_info[2]) from e
  File "/home/carloslessa/FCD/POSTECH/tech-challenge-1/venv/lib/python3.10/site-packages/sqlalchemy/engine/base.py", line 145, in __init__
    self._dbapi_connection = engine.raw_connection()
  File "/home/carloslessa/FCD/POSTECH/tech-challenge-1/venv/lib/python3.10/site-packages/sqlalchemy/engine/base.py", line 3297, in raw_connection
    return self.pool.connect()
  File "/home/carloslessa/FCD/POSTECH/tech-challenge-1/venv/lib/python3.10/site-packages/sqlalchemy/pool/base.py", line 449, in connect
    return _ConnectionFairy._checkout(self)
  File "/home/carloslessa/FCD/POSTECH/tech-challenge-1/venv/lib/python3.10/site-packages/sqlalchemy/pool/base.py", line 1264, in _checkout
    fairy = _ConnectionRecord.checkout(pool)
  File "/home/carloslessa/FCD/POSTECH/tech-challenge-1/venv/lib/python3.10/site-packages/sqlalchemy/pool/base.py", line 718, in checkout
    with util.safe_reraise():
  File "/home/carloslessa/FCD/POSTECH/tech-challenge-1/venv/lib/python3.10/site-packages/sqlalchemy/util/langhelpers.py", line 224, in __exit__
    raise exc_value.with_traceback(exc_tb)
  File "/home/carloslessa/FCD/POSTECH/tech-challenge-1/venv/lib/python3.10/site-packages/sqlalchemy/pool/base.py", line 716, in checkout
    dbapi_connection = rec.get_connection()
  File "/home/carloslessa/FCD/POSTECH/tech-challenge-1/venv/lib/python3.10/site-packages/sqlalchemy/pool/base.py", line 838, in get_connection
    self.__connect()
  File "/home/carloslessa/FCD/POSTECH/tech-challenge-1/venv/lib/python3.10/site-packages/sqlalchemy/pool/base.py", line 901, in __connect
    with util.safe_reraise():
  File "/home/carloslessa/FCD/POSTECH/tech-challenge-1/venv/lib/python3.10/site-packages/sqlalchemy/util/langhelpers.py", line 224, in __exit__
    raise exc_value.with_traceback(exc_tb)
  File "/home/carloslessa/FCD/POSTECH/tech-challenge-1/venv/lib/python3.10/site-packages/sqlalchemy/pool/base.py", line 897, in __connect
    self.dbapi_connection = connection = pool._invoke_creator(self)
  File "/home/carloslessa/FCD/POSTECH/tech-challenge-1/venv/lib/python3.10/site-packages/sqlalchemy/engine/create.py", line 646, in connect
    return dialect.connect(*cargs, **cparams)
  File "/home/carloslessa/FCD/POSTECH/tech-challenge-1/venv/lib/python3.10/site-packages/sqlalchemy/engine/default.py", line 625, in connect
    return self.loaded_dbapi.connect(*cargs, **cparams)  # type: ignore[no-any-return]  # NOQA: E501
  File "/home/carloslessa/FCD/POSTECH/tech-challenge-1/venv/lib/python3.10/site-packages/psycopg2/__init__.py", line 122, in connect
    conn = _connect(dsn, connection_factory=connection_factory, **kwasync)
sqlalchemy.exc.OperationalError: (psycopg2.OperationalError) connection to server at "localhost" (127.0.0.1), port 5433 failed: Connection refused
	Is the server running on that host and accepting TCP/IP connections?

(Background on this error at: https://sqlalche.me/e/20/e3q8)

During handling of the above exception, another exception occurred:

Traceback (most recent call last):
  File "/home/carloslessa/FCD/POSTECH/tech-challenge-1/src/services/producao_service.py", line 44, in get_por_ano
    self._repo.salvar_ou_atualizar(dados, ano)
  File "/home/carloslessa/FCD/POSTECH/tech-challenge-1/src/repositories/raw_repository.py", line 75, in salvar_ou_atualizar
    raise ErroConexaoBD(str(e))
src.repositories.exceptions.ErroConexaoBD: Erro de conexão com o banco: (psycopg2.OperationalError) connection to server at "localhost" (127.0.0.1), port 5433 failed: Connection refused
	Is the server running on that host and accepting TCP/IP connections?

(Background on this error at: https://sqlalche.me/e/20/e3q8)
[2025-05-20 20:10:17] [ERROR] [src.services.producao_service] Erro de persistência: Erro de conexão com o banco: (psycopg2.OperationalError) connection to server at "localhost" (127.0.0.1), port 5433 failed: Connection refused
	Is the server running on that host and accepting TCP/IP connections?

(Background on this error at: https://sqlalche.me/e/20/e3q8)
[2025-05-20 20:19:23] [WARNING] [src.services.comercializacao_service] Impossível salvar cache: Erro de conexão com o banco: (psycopg2.OperationalError) connection to server at "localhost" (127.0.0.1), port 5433 failed: Connection refused
	Is the server running on that host and accepting TCP/IP connections?

(Background on this error at: https://sqlalche.me/e/20/e3q8); continuando com dados do site.
[2025-05-20 20:20:47] [WARNING] [src.services.producao_service] Impossível salvar cache: Erro de conexão com o banco: (psycopg2.OperationalError) connection to server at "localhost" (127.0.0.1), port 5433 failed: Connection refused
	Is the server running on that host and accepting TCP/IP connections?

(Background on this error at: https://sqlalche.me/e/20/e3q8); continuando com dados do site.
[2025-05-20 20:23:50] [WARNING] [src.services.processamento_service] Impossível salvar cache: Erro de conexão com o banco: (psycopg2.OperationalError) connection to server at "localhost" (127.0.0.1), port 5433 failed: Connection refused
	Is the server running on that host and accepting TCP/IP connections?

(Background on this error at: https://sqlalche.me/e/20/e3q8); continuando com dados do site.
[2025-05-20 20:24:04] [WARNING] [src.services.importacao_service] Impossível salvar cache: Erro de conexão com o banco: (psycopg2.OperationalError) connection to server at "localhost" (127.0.0.1), port 5433 failed: Connection refused
	Is the server running on that host and accepting TCP/IP connections?

(Background on this error at: https://sqlalche.me/e/20/e3q8); continuando com dados do site.
[2025-05-20 20:24:21] [WARNING] [src.services.exportacao_service] Impossível salvar cache: Erro de conexão com o banco: (psycopg2.OperationalError) connection to server at "localhost" (127.0.0.1), port 5433 failed: Connection refused
	Is the server running on that host and accepting TCP/IP connections?

(Background on this error at: https://sqlalche.me/e/20/e3q8); continuando com dados do site.
